<?xml version="1.0" encoding="UTF-8"?>
<testng-results skipped="0" failed="1" total="2" passed="1">
  <reporter-output>
  </reporter-output>
  <suite name="Default suite" duration-ms="94875" started-at="2023-12-14T05:51:36Z" finished-at="2023-12-14T05:53:11Z">
    <groups>
    </groups>
    <test name="Default test" duration-ms="94875" started-at="2023-12-14T05:51:36Z" finished-at="2023-12-14T05:53:11Z">
      <class name="com.qa.testcases.verifyAmber">
        <test-method status="PASS" signature="lunchAmberSite()[pri:0, instance:com.qa.testcases.verifyAmber@167135c]" name="lunchAmberSite" is-config="true" duration-ms="29435" started-at="2023-12-14T11:21:36Z" finished-at="2023-12-14T11:22:05Z">
          <reporter-output>
          </reporter-output>
        </test-method> <!-- lunchAmberSite -->
        <test-method status="FAIL" signature="verifyTitleOfLodge()[pri:0, instance:com.qa.testcases.verifyAmber@167135c]" name="verifyTitleOfLodge" duration-ms="60221" started-at="2023-12-14T11:22:06Z" finished-at="2023-12-14T11:23:06Z">
          <exception class="java.lang.AssertionError">
            <message>
              <![CDATA[Incorrect North Lodge Text expected [North lodge] but found [North Lodge, London]]]>
            </message>
            <full-stacktrace>
              <![CDATA[java.lang.AssertionError: Incorrect North Lodge Text expected [North lodge] but found [North Lodge, London]
	at org.testng.Assert.fail(Assert.java:94)
	at org.testng.Assert.failNotEquals(Assert.java:513)
	at org.testng.Assert.assertEqualsImpl(Assert.java:135)
	at org.testng.Assert.assertEquals(Assert.java:116)
	at org.testng.Assert.assertEquals(Assert.java:190)
	at com.qa.testcases.verifyAmber.verifyTitleOfLodge(verifyAmber.java:37)
	at sun.reflect.NativeMethodAccessorImpl.invoke0(Native Method)
	at sun.reflect.NativeMethodAccessorImpl.invoke(NativeMethodAccessorImpl.java:62)
	at sun.reflect.DelegatingMethodAccessorImpl.invoke(DelegatingMethodAccessorImpl.java:43)
	at java.lang.reflect.Method.invoke(Method.java:498)
	at org.testng.internal.MethodInvocationHelper.invokeMethod(MethodInvocationHelper.java:86)
	at org.testng.internal.Invoker.invokeMethod(Invoker.java:645)
	at org.testng.internal.Invoker.invokeTestMethod(Invoker.java:822)
	at org.testng.internal.Invoker.invokeTestMethods(Invoker.java:1130)
	at org.testng.internal.TestMethodWorker.invokeTestMethods(TestMethodWorker.java:129)
	at org.testng.internal.TestMethodWorker.run(TestMethodWorker.java:112)
	at org.testng.TestRunner.privateRun(TestRunner.java:782)
	at org.testng.TestRunner.run(TestRunner.java:632)
	at org.testng.SuiteRunner.runTest(SuiteRunner.java:366)
	at org.testng.SuiteRunner.runSequentially(SuiteRunner.java:361)
	at org.testng.SuiteRunner.privateRun(SuiteRunner.java:319)
	at org.testng.SuiteRunner.run(SuiteRunner.java:268)
	at org.testng.SuiteRunnerWorker.runSuite(SuiteRunnerWorker.java:52)
	at org.testng.SuiteRunnerWorker.run(SuiteRunnerWorker.java:86)
	at org.testng.TestNG.runSuitesSequentially(TestNG.java:1244)
	at org.testng.TestNG.runSuitesLocally(TestNG.java:1169)
	at org.testng.TestNG.run(TestNG.java:1064)
	at org.testng.remote.RemoteTestNG.run(RemoteTestNG.java:113)
	at org.testng.remote.RemoteTestNG.initAndRun(RemoteTestNG.java:206)
	at org.testng.remote.RemoteTestNG.main(RemoteTestNG.java:177)
]]>
            </full-stacktrace>
          </exception> <!-- java.lang.AssertionError -->
          <reporter-output>
          </reporter-output>
        </test-method> <!-- verifyTitleOfLodge -->
        <test-method status="PASS" signature="verifyAddressOfLodge()[pri:1, instance:com.qa.testcases.verifyAmber@167135c]" name="verifyAddressOfLodge" duration-ms="5058" started-at="2023-12-14T11:23:06Z" depends-on-methods="com.qa.testcases.verifyAmber.verifyTitleOfLodge" finished-at="2023-12-14T11:23:11Z">
          <reporter-output>
          </reporter-output>
        </test-method> <!-- verifyAddressOfLodge -->
      </class> <!-- com.qa.testcases.verifyAmber -->
    </test> <!-- Default test -->
  </suite> <!-- Default suite -->
</testng-results>
